package stevekung.mods.moreplanets.core.spacestation.jupiter;

import java.util.Random;

import micdoodle8.mods.galacticraft.core.blocks.GCBlocks;
import net.minecraft.init.Blocks;
import net.minecraft.world.World;
import net.minecraft.world.gen.feature.WorldGenerator;
import stevekung.mods.moreplanets.core.init.MPBlocks;

public class WorldGenJupiterSpaceStation extends WorldGenerator
{
	@Override
	public boolean generate(World world, Random rand, int x, int y, int z)
	{
		world.setBlock(x + 0, y + 0, z + 0, GCBlocks.basicBlock, 4, 3);
		world.setBlock(x + 0, y + 0, z + 1, GCBlocks.basicBlock, 4, 3);
		world.setBlock(x + 0, y + 0, z + 2, GCBlocks.basicBlock, 4, 3);
		world.setBlock(x + 0, y + 0, z + 3, GCBlocks.basicBlock, 4, 3);
		world.setBlock(x + 0, y + 0, z + 4, GCBlocks.basicBlock, 4, 3);
		world.setBlock(x + 0, y + 0, z + 5, GCBlocks.basicBlock, 4, 3);
		world.setBlock(x + 0, y + 0, z + 6, GCBlocks.basicBlock, 4, 3);
		world.setBlock(x + 0, y + 1, z + 0, GCBlocks.basicBlock, 4, 3);
		world.setBlock(x + 0, y + 1, z + 1, GCBlocks.basicBlock, 4, 3);
		world.setBlock(x + 0, y + 1, z + 2, GCBlocks.basicBlock, 4, 3);
		world.setBlock(x + 0, y + 1, z + 3, GCBlocks.basicBlock, 4, 3);
		world.setBlock(x + 0, y + 1, z + 4, GCBlocks.basicBlock, 4, 3);
		world.setBlock(x + 0, y + 1, z + 5, GCBlocks.basicBlock, 4, 3);
		world.setBlock(x + 0, y + 1, z + 6, GCBlocks.basicBlock, 4, 3);
		world.setBlock(x + 1, y + 0, z + 0, GCBlocks.basicBlock, 4, 3);
		world.setBlock(x + 1, y + 0, z + 1, GCBlocks.basicBlock, 4, 3);
		world.setBlock(x + 1, y + 0, z + 2, GCBlocks.basicBlock, 4, 3);
		world.setBlock(x + 1, y + 0, z + 3, GCBlocks.basicBlock, 4, 3);
		world.setBlock(x + 1, y + 0, z + 4, GCBlocks.basicBlock, 4, 3);
		world.setBlock(x + 1, y + 0, z + 5, GCBlocks.basicBlock, 4, 3);
		world.setBlock(x + 1, y + 0, z + 6, GCBlocks.basicBlock, 4, 3);

		world.setBlock(x + 1, y + 1, z + 0, GCBlocks.basicBlock, 4, 3);
		world.setBlock(x + 1, y + 1, z + 6, GCBlocks.basicBlock, 4, 3);
		world.setBlock(x + 2, y + 0, z + 0, GCBlocks.basicBlock, 4, 3);
		world.setBlock(x + 2, y + 0, z + 1, GCBlocks.basicBlock, 4, 3);
		world.setBlock(x + 2, y + 0, z + 2, Blocks.iron_block, 0, 3);
		world.setBlock(x + 2, y + 0, z + 3, Blocks.iron_block, 0, 3);
		world.setBlock(x + 2, y + 0, z + 4, Blocks.iron_block, 0, 3);
		world.setBlock(x + 2, y + 0, z + 5, GCBlocks.basicBlock, 4, 3);
		world.setBlock(x + 2, y + 0, z + 6, GCBlocks.basicBlock, 4, 3);
		world.setBlock(x + 2, y + 1, z + 0, GCBlocks.basicBlock, 4, 3);
		world.setBlock(x + 2, y + 1, z + 6, GCBlocks.basicBlock, 4, 3);
		world.setBlock(x + 3, y + 0, z + 0, GCBlocks.basicBlock, 4, 3);
		world.setBlock(x + 3, y + 0, z + 1, GCBlocks.basicBlock, 4, 3);
		world.setBlock(x + 3, y + 0, z + 2, Blocks.iron_block, 0, 3);
		world.setBlock(x + 3, y + 0, z + 3, Blocks.iron_block, 0, 3);
		world.setBlock(x + 3, y + 0, z + 4, Blocks.iron_block, 0, 3);
		world.setBlock(x + 3, y + 0, z + 5, GCBlocks.basicBlock, 4, 3);
		world.setBlock(x + 3, y + 0, z + 6, GCBlocks.basicBlock, 4, 3);
		world.setBlock(x + 3, y + 1, z + 0, GCBlocks.basicBlock, 4, 3);

		world.setBlock(x + 3, y + 1, z + 6, GCBlocks.basicBlock, 4, 3);
		world.setBlock(x + 4, y + 0, z + 0, GCBlocks.basicBlock, 4, 3);
		world.setBlock(x + 4, y + 0, z + 1, GCBlocks.basicBlock, 4, 3);
		world.setBlock(x + 4, y + 0, z + 2, Blocks.iron_block, 0, 3);
		world.setBlock(x + 4, y + 0, z + 3, Blocks.iron_block, 0, 3);
		world.setBlock(x + 4, y + 0, z + 4, Blocks.iron_block, 0, 3);
		world.setBlock(x + 4, y + 0, z + 5, GCBlocks.basicBlock, 4, 3);
		world.setBlock(x + 4, y + 0, z + 6, GCBlocks.basicBlock, 4, 3);
		world.setBlock(x + 4, y + 1, z + 0, GCBlocks.basicBlock, 4, 3);
		world.setBlock(x + 4, y + 1, z + 6, GCBlocks.basicBlock, 4, 3);
		world.setBlock(x + 5, y + 0, z + 0, GCBlocks.basicBlock, 4, 3);
		world.setBlock(x + 5, y + 0, z + 1, GCBlocks.basicBlock, 4, 3);
		world.setBlock(x + 5, y + 0, z + 2, GCBlocks.basicBlock, 4, 3);
		world.setBlock(x + 5, y + 0, z + 3, GCBlocks.basicBlock, 4, 3);
		world.setBlock(x + 5, y + 0, z + 4, GCBlocks.basicBlock, 4, 3);
		world.setBlock(x + 5, y + 0, z + 5, GCBlocks.basicBlock, 4, 3);
		world.setBlock(x + 5, y + 0, z + 6, GCBlocks.basicBlock, 4, 3);
		world.setBlock(x + 5, y + 1, z + 0, GCBlocks.basicBlock, 4, 3);
		world.setBlock(x + 5, y + 1, z + 6, GCBlocks.basicBlock, 4, 3);
		world.setBlock(x + 6, y + 1, z + 0, GCBlocks.basicBlock, 4, 3);
		world.setBlock(x + 6, y + 1, z + 1, GCBlocks.basicBlock, 4, 3);
		world.setBlock(x + 6, y + 1, z + 2, GCBlocks.basicBlock, 4, 3);
		world.setBlock(x + 6, y + 1, z + 3, GCBlocks.basicBlock, 4, 3);
		world.setBlock(x + 6, y + 1, z + 4, GCBlocks.basicBlock, 4, 3);
		world.setBlock(x + 6, y + 1, z + 5, GCBlocks.basicBlock, 4, 3);
		world.setBlock(x + 6, y + 1, z + 6, GCBlocks.basicBlock, 4, 3);
		world.setBlock(x + 6, y + 2, z + 0, GCBlocks.basicBlock, 4, 3);
		world.setBlock(x + 6, y + 2, z + 6, GCBlocks.basicBlock, 4, 3);
		world.setBlock(x + 6, y + 3, z + 0, GCBlocks.basicBlock, 4, 3);
		world.setBlock(x + 6, y + 3, z + 6, GCBlocks.basicBlock, 4, 3);
		world.setBlock(x + 6, y + 4, z + 0, GCBlocks.basicBlock, 4, 3);
		world.setBlock(x + 6, y + 4, z + 6, GCBlocks.basicBlock, 4, 3);
		world.setBlock(x + 6, y + 5, z + 0, GCBlocks.basicBlock, 4, 3);
		world.setBlock(x + 6, y + 5, z + 1, GCBlocks.basicBlock, 4, 3);
		world.setBlock(x + 6, y + 5, z + 2, GCBlocks.basicBlock, 4, 3);
		world.setBlock(x + 6, y + 5, z + 3, GCBlocks.basicBlock, 4, 3);
		world.setBlock(x + 6, y + 5, z + 4, GCBlocks.basicBlock, 4, 3);
		world.setBlock(x + 6, y + 5, z + 5, GCBlocks.basicBlock, 4, 3);
		world.setBlock(x + 6, y + 5, z + 6, GCBlocks.basicBlock, 4, 3);
		world.setBlock(x + 7, y + 1, z + 0, GCBlocks.basicBlock, 4, 3);
		world.setBlock(x + 7, y + 1, z + 1, GCBlocks.basicBlock, 4, 3);
		world.setBlock(x + 7, y + 1, z + 2, GCBlocks.basicBlock, 4, 3);
		world.setBlock(x + 7, y + 1, z + 3, GCBlocks.basicBlock, 4, 3);
		world.setBlock(x + 7, y + 1, z + 4, GCBlocks.basicBlock, 4, 3);
		world.setBlock(x + 7, y + 1, z + 5, GCBlocks.basicBlock, 4, 3);
		world.setBlock(x + 7, y + 1, z + 6, GCBlocks.basicBlock, 4, 3);
		world.setBlock(x + 7, y + 2, z + 0, GCBlocks.basicBlock, 4, 3);
		world.setBlock(x + 7, y + 2, z + 1, GCBlocks.basicBlock, 4, 3);
		world.setBlock(x + 7, y + 2, z + 5, GCBlocks.basicBlock, 4, 3);
		world.setBlock(x + 7, y + 2, z + 6, GCBlocks.basicBlock, 4, 3);
		world.setBlock(x + 7, y + 3, z + 0, GCBlocks.basicBlock, 4, 3);
		world.setBlock(x + 7, y + 3, z + 1, GCBlocks.basicBlock, 4, 3);
		world.setBlock(x + 7, y + 3, z + 5, GCBlocks.basicBlock, 4, 3);
		world.setBlock(x + 7, y + 3, z + 6, GCBlocks.basicBlock, 4, 3);
		world.setBlock(x + 7, y + 4, z + 0, GCBlocks.basicBlock, 4, 3);
		world.setBlock(x + 7, y + 4, z + 1, GCBlocks.basicBlock, 4, 3);
		world.setBlock(x + 7, y + 4, z + 5, GCBlocks.basicBlock, 4, 3);
		world.setBlock(x + 7, y + 4, z + 6, GCBlocks.basicBlock, 4, 3);
		world.setBlock(x + 7, y + 5, z + 0, GCBlocks.basicBlock, 4, 3);
		world.setBlock(x + 7, y + 5, z + 1, GCBlocks.basicBlock, 4, 3);
		world.setBlock(x + 7, y + 5, z + 2, GCBlocks.basicBlock, 4, 3);
		world.setBlock(x + 7, y + 5, z + 3, GCBlocks.basicBlock, 4, 3);
		world.setBlock(x + 7, y + 5, z + 4, GCBlocks.basicBlock, 4, 3);
		world.setBlock(x + 7, y + 5, z + 5, GCBlocks.basicBlock, 4, 3);
		world.setBlock(x + 7, y + 5, z + 6, GCBlocks.basicBlock, 4, 3);
		world.setBlock(x + 7, y + 6, z + 0, GCBlocks.basicBlock, 4, 3);
		world.setBlock(x + 7, y + 6, z + 1, GCBlocks.basicBlock, 4, 3);
		world.setBlock(x + 7, y + 6, z + 2, GCBlocks.basicBlock, 4, 3);
		world.setBlock(x + 7, y + 6, z + 3, GCBlocks.basicBlock, 4, 3);
		world.setBlock(x + 7, y + 6, z + 4, GCBlocks.basicBlock, 4, 3);
		world.setBlock(x + 7, y + 6, z + 5, GCBlocks.basicBlock, 4, 3);
		world.setBlock(x + 7, y + 6, z + 6, GCBlocks.basicBlock, 4, 3);
		world.setBlock(x + 8, y + 1, z + 0, GCBlocks.basicBlock, 4, 3);
		world.setBlock(x + 8, y + 1, z + 1, GCBlocks.basicBlock, 4, 3);
		world.setBlock(x + 8, y + 1, z + 2, GCBlocks.basicBlock, 4, 3);
		world.setBlock(x + 8, y + 1, z + 3, GCBlocks.basicBlock, 4, 3);
		world.setBlock(x + 8, y + 1, z + 4, GCBlocks.basicBlock, 4, 3);
		world.setBlock(x + 8, y + 1, z + 5, GCBlocks.basicBlock, 4, 3);
		world.setBlock(x + 8, y + 1, z + 6, GCBlocks.basicBlock, 4, 3);
		world.setBlock(x + 8, y + 2, z + 0, GCBlocks.basicBlock, 4, 3);
		world.setBlock(x + 8, y + 2, z + 6, GCBlocks.basicBlock, 4, 3);
		world.setBlock(x + 8, y + 3, z + 0, MPBlocks.tinted_glass_pane, 8, 3);
		world.setBlock(x + 8, y + 3, z + 6, MPBlocks.tinted_glass_pane, 8, 3);
		world.setBlock(x + 8, y + 4, z + 0, GCBlocks.basicBlock, 4, 3);
		world.setBlock(x + 8, y + 4, z + 6, GCBlocks.basicBlock, 4, 3);
		world.setBlock(x + 8, y + 5, z + 0, GCBlocks.basicBlock, 4, 3);
		world.setBlock(x + 8, y + 5, z + 6, GCBlocks.basicBlock, 4, 3);
		world.setBlock(x + 8, y + 6, z + 0, GCBlocks.basicBlock, 4, 3);
		world.setBlock(x + 8, y + 6, z + 1, GCBlocks.basicBlock, 4, 3);
		world.setBlock(x + 8, y + 6, z + 2, GCBlocks.basicBlock, 4, 3);
		world.setBlock(x + 8, y + 6, z + 3, GCBlocks.basicBlock, 4, 3);
		world.setBlock(x + 8, y + 6, z + 4, GCBlocks.basicBlock, 4, 3);
		world.setBlock(x + 8, y + 6, z + 5, GCBlocks.basicBlock, 4, 3);
		world.setBlock(x + 8, y + 6, z + 6, GCBlocks.basicBlock, 4, 3);
		world.setBlock(x + 9, y + 1, z + 0, GCBlocks.basicBlock, 4, 3);
		world.setBlock(x + 9, y + 1, z + 1, GCBlocks.basicBlock, 4, 3);
		world.setBlock(x + 9, y + 1, z + 2, MPBlocks.tinted_glass, 8, 3);
		world.setBlock(x + 9, y + 1, z + 3, MPBlocks.tinted_glass, 8, 3);
		world.setBlock(x + 9, y + 1, z + 4, MPBlocks.tinted_glass, 8, 3);
		world.setBlock(x + 9, y + 1, z + 5, GCBlocks.basicBlock, 4, 3);
		world.setBlock(x + 9, y + 1, z + 6, GCBlocks.basicBlock, 4, 3);
		world.setBlock(x + 9, y + 5, z + 0, GCBlocks.basicBlock, 4, 3);
		world.setBlock(x + 9, y + 5, z + 6, GCBlocks.basicBlock, 4, 3);
		world.setBlock(x + 9, y + 6, z + 0, GCBlocks.basicBlock, 4, 3);
		world.setBlock(x + 9, y + 6, z + 1, GCBlocks.basicBlock, 4, 3);
		world.setBlock(x + 9, y + 6, z + 2, GCBlocks.basicBlock, 4, 3);
		world.setBlock(x + 9, y + 6, z + 3, GCBlocks.basicBlock, 4, 3);
		world.setBlock(x + 9, y + 6, z + 4, GCBlocks.basicBlock, 4, 3);
		world.setBlock(x + 9, y + 6, z + 5, GCBlocks.basicBlock, 4, 3);
		world.setBlock(x + 9, y + 6, z + 6, GCBlocks.basicBlock, 4, 3);
		world.setBlock(x + 10, y + 1, z + 0, GCBlocks.basicBlock, 4, 3);
		world.setBlock(x + 10, y + 1, z + 1, GCBlocks.basicBlock, 4, 3);
		world.setBlock(x + 10, y + 1, z + 2, MPBlocks.tinted_glass, 8, 3);
		world.setBlock(x + 10, y + 1, z + 3, MPBlocks.tinted_glass, 8, 3);
		world.setBlock(x + 10, y + 1, z + 4, MPBlocks.tinted_glass, 8, 3);
		world.setBlock(x + 10, y + 1, z + 5, GCBlocks.basicBlock, 4, 3);
		world.setBlock(x + 10, y + 1, z + 6, GCBlocks.basicBlock, 4, 3);

		world.setBlock(x + 10, y + 5, z + 0, GCBlocks.basicBlock, 4, 3);
		world.setBlock(x + 10, y + 5, z + 6, GCBlocks.basicBlock, 4, 3);
		world.setBlock(x + 10, y + 6, z + 0, GCBlocks.basicBlock, 4, 3);
		world.setBlock(x + 10, y + 6, z + 1, GCBlocks.basicBlock, 4, 3);
		world.setBlock(x + 10, y + 6, z + 2, GCBlocks.basicBlock, 4, 3);
		world.setBlock(x + 10, y + 6, z + 3, GCBlocks.basicBlock, 4, 3);
		world.setBlock(x + 10, y + 6, z + 4, GCBlocks.basicBlock, 4, 3);
		world.setBlock(x + 10, y + 6, z + 5, GCBlocks.basicBlock, 4, 3);
		world.setBlock(x + 10, y + 6, z + 6, GCBlocks.basicBlock, 4, 3);
		world.setBlock(x + 11, y + 1, z + 0, GCBlocks.basicBlock, 4, 3);
		world.setBlock(x + 11, y + 1, z + 1, GCBlocks.basicBlock, 4, 3);
		world.setBlock(x + 11, y + 1, z + 2, MPBlocks.tinted_glass, 8, 3);
		world.setBlock(x + 11, y + 1, z + 3, MPBlocks.tinted_glass, 8, 3);
		world.setBlock(x + 11, y + 1, z + 4, MPBlocks.tinted_glass, 8, 3);
		world.setBlock(x + 11, y + 1, z + 5, GCBlocks.basicBlock, 4, 3);
		world.setBlock(x + 11, y + 1, z + 6, GCBlocks.basicBlock, 4, 3);
		world.setBlock(x + 11, y + 5, z + 0, GCBlocks.basicBlock, 4, 3);
		world.setBlock(x + 11, y + 5, z + 6, GCBlocks.basicBlock, 4, 3);
		world.setBlock(x + 11, y + 6, z + 0, GCBlocks.basicBlock, 4, 3);
		world.setBlock(x + 11, y + 6, z + 1, GCBlocks.basicBlock, 4, 3);
		world.setBlock(x + 11, y + 6, z + 2, GCBlocks.basicBlock, 4, 3);
		world.setBlock(x + 11, y + 6, z + 3, GCBlocks.basicBlock, 4, 3);
		world.setBlock(x + 11, y + 6, z + 4, GCBlocks.basicBlock, 4, 3);
		world.setBlock(x + 11, y + 6, z + 5, GCBlocks.basicBlock, 4, 3);
		world.setBlock(x + 11, y + 6, z + 6, GCBlocks.basicBlock, 4, 3);
		world.setBlock(x + 12, y + 1, z + 0, GCBlocks.basicBlock, 4, 3);
		world.setBlock(x + 12, y + 1, z + 1, GCBlocks.basicBlock, 4, 3);
		world.setBlock(x + 12, y + 1, z + 2, GCBlocks.basicBlock, 4, 3);
		world.setBlock(x + 12, y + 1, z + 3, GCBlocks.basicBlock, 4, 3);
		world.setBlock(x + 12, y + 1, z + 4, GCBlocks.basicBlock, 4, 3);
		world.setBlock(x + 12, y + 1, z + 5, GCBlocks.basicBlock, 4, 3);
		world.setBlock(x + 12, y + 1, z + 6, GCBlocks.basicBlock, 4, 3);
		world.setBlock(x + 12, y + 2, z + 0, GCBlocks.basicBlock, 4, 3);
		world.setBlock(x + 12, y + 2, z + 6, GCBlocks.basicBlock, 4, 3);
		world.setBlock(x + 12, y + 3, z + 0, MPBlocks.tinted_glass_pane, 8, 3);
		world.setBlock(x + 12, y + 3, z + 6, MPBlocks.tinted_glass_pane, 8, 3);
		world.setBlock(x + 12, y + 4, z + 0, GCBlocks.basicBlock, 4, 3);
		world.setBlock(x + 12, y + 4, z + 6, GCBlocks.basicBlock, 4, 3);
		world.setBlock(x + 12, y + 5, z + 0, GCBlocks.basicBlock, 4, 3);
		world.setBlock(x + 12, y + 5, z + 6, GCBlocks.basicBlock, 4, 3);
		world.setBlock(x + 12, y + 6, z + 0, GCBlocks.basicBlock, 4, 3);
		world.setBlock(x + 12, y + 6, z + 1, GCBlocks.basicBlock, 4, 3);
		world.setBlock(x + 12, y + 6, z + 2, GCBlocks.basicBlock, 4, 3);
		world.setBlock(x + 12, y + 6, z + 3, GCBlocks.basicBlock, 4, 3);
		world.setBlock(x + 12, y + 6, z + 4, GCBlocks.basicBlock, 4, 3);
		world.setBlock(x + 12, y + 6, z + 5, GCBlocks.basicBlock, 4, 3);
		world.setBlock(x + 12, y + 6, z + 6, GCBlocks.basicBlock, 4, 3);
		world.setBlock(x + 13, y + 1, z + 0, GCBlocks.basicBlock, 4, 3);
		world.setBlock(x + 13, y + 1, z + 1, GCBlocks.basicBlock, 4, 3);
		world.setBlock(x + 13, y + 1, z + 2, GCBlocks.basicBlock, 4, 3);
		world.setBlock(x + 13, y + 1, z + 3, GCBlocks.basicBlock, 4, 3);
		world.setBlock(x + 13, y + 1, z + 4, GCBlocks.basicBlock, 4, 3);
		world.setBlock(x + 13, y + 1, z + 5, GCBlocks.basicBlock, 4, 3);
		world.setBlock(x + 13, y + 1, z + 6, GCBlocks.basicBlock, 4, 3);
		world.setBlock(x + 13, y + 2, z + 0, GCBlocks.basicBlock, 4, 3);
		world.setBlock(x + 13, y + 2, z + 1, GCBlocks.basicBlock, 4, 3);
		world.setBlock(x + 13, y + 2, z + 5, GCBlocks.basicBlock, 4, 3);
		world.setBlock(x + 13, y + 2, z + 6, GCBlocks.basicBlock, 4, 3);
		world.setBlock(x + 13, y + 3, z + 0, GCBlocks.basicBlock, 4, 3);
		world.setBlock(x + 13, y + 3, z + 1, MPBlocks.tinted_glass_pane, 8, 3);
		world.setBlock(x + 13, y + 3, z + 5, MPBlocks.tinted_glass_pane, 8, 3);
		world.setBlock(x + 13, y + 3, z + 6, GCBlocks.basicBlock, 4, 3);
		world.setBlock(x + 13, y + 4, z + 0, GCBlocks.basicBlock, 4, 3);
		world.setBlock(x + 13, y + 4, z + 1, GCBlocks.basicBlock, 4, 3);
		world.setBlock(x + 13, y + 4, z + 5, GCBlocks.basicBlock, 4, 3);
		world.setBlock(x + 13, y + 4, z + 6, GCBlocks.basicBlock, 4, 3);
		world.setBlock(x + 13, y + 5, z + 0, GCBlocks.basicBlock, 4, 3);
		world.setBlock(x + 13, y + 5, z + 1, GCBlocks.basicBlock, 4, 3);
		world.setBlock(x + 13, y + 5, z + 2, GCBlocks.basicBlock, 4, 3);
		world.setBlock(x + 13, y + 5, z + 3, GCBlocks.basicBlock, 4, 3);
		world.setBlock(x + 13, y + 5, z + 4, GCBlocks.basicBlock, 4, 3);
		world.setBlock(x + 13, y + 5, z + 5, GCBlocks.basicBlock, 4, 3);
		world.setBlock(x + 13, y + 5, z + 6, GCBlocks.basicBlock, 4, 3);
		world.setBlock(x + 13, y + 6, z + 0, GCBlocks.basicBlock, 4, 3);
		world.setBlock(x + 13, y + 6, z + 1, GCBlocks.basicBlock, 4, 3);
		world.setBlock(x + 13, y + 6, z + 2, GCBlocks.basicBlock, 4, 3);
		world.setBlock(x + 13, y + 6, z + 3, GCBlocks.basicBlock, 4, 3);
		world.setBlock(x + 13, y + 6, z + 4, GCBlocks.basicBlock, 4, 3);
		world.setBlock(x + 13, y + 6, z + 5, GCBlocks.basicBlock, 4, 3);
		world.setBlock(x + 13, y + 6, z + 6, GCBlocks.basicBlock, 4, 3);
		return true;
	}
}